<?xml version="1.0"?>
<robot xmlns:xacro="http://www.ros.org/wiki/xacro">
    
    <link name="base_footprint"/>
    <joint name="base_joint" type="fixed">
        <parent link="base_footprint"/><child link="base_link"/>
        <origin xyz="0 0 0.05" rpy="0 0 0"/>
    </joint>

    <link name="base_link">
        <inertial>
            <origin xyz="0.05 0.0 -0.02" rpy="0 0 0" /> 
            <mass value="4.0" />
            <inertia ixx="0.1" ixy="0.0" ixz="0.0" iyy="0.1" iyz="0.0" izz="0.1" />
        </inertial>
        <visual>
            <geometry><mesh filename="package://assem1/meshes/base_link.STL" /></geometry>
            <material name="metallic_blue"/>
        </visual>
        <collision>
            <geometry><box size="0.3 0.2 0.1" /></geometry>
        </collision>
    </link>

    <xacro:macro name="wheel" params="prefix y_reflect">
        <link name="${prefix}_wheel">
            <inertial>
                <mass value="0.4" />
                <inertia ixx="0.01" ixy="0.0" ixz="0.0" iyy="0.01" iyz="0.0" izz="0.01" />
            </inertial>
            <visual>
                <geometry><mesh filename="package://assem1/meshes/${prefix}_wheel.STL" /></geometry>
                <material name="dark_gray"/>
            </visual>
            <collision>
                <geometry><cylinder radius="0.035" length="0.025" /></geometry>
            </collision>
        </link>

        <joint name="${prefix}_wheel_joint" type="continuous">
            <parent link="base_link"/>
            <child link="${prefix}_wheel"/>
            <origin xyz="${prefix == 'left' ? 0.069 : -0.070} ${y_reflect * 0.036} -0.033" rpy="0 0 0"/>
            <axis xyz="1 0 0"/>
        </joint>
    </xacro:macro>

    <xacro:wheel prefix="left" y_reflect="-1" />
    <xacro:wheel prefix="right" y_reflect="1" />

    <link name="caster">
        <inertial><mass value="0.1" /><inertia ixx="0.001" ixy="0" ixz="0" iyy="0.001" iyz="0" izz="0.001"/></inertial>
        <visual><geometry><sphere radius="0.02"/></geometry></visual>
        <collision><geometry><sphere radius="0.02"/></geometry></collision>
    </link>
    <joint name="caster_joint" type="fixed">
        <parent link="base_link"/><child link="caster"/>
        <origin xyz="0.12 0 -0.048"/>
    </joint>

    <gazebo>
        <plugin filename="gz-sim-diff-drive-system" name="gz::sim::systems::DiffDrive">
            <left_joint>left_wheel_joint</left_joint>
            <right_joint>right_wheel_joint</right_joint>
            <wheel_separation>0.14</wheel_separation>
            <wheel_radius>0.035</wheel_radius>
            <topic>cmd_vel</topic>
            <odom_topic>odom</odom_topic>
        </plugin>
    </gazebo>
</robot>
